Traceback (most recent call last):
  File "/usr/local/lib/python3.10/site-packages/jupyter_core/utils/__init__.py", line 154, in wrapped
    asyncio.get_running_loop()
RuntimeError: no running event loop

During handling of the above exception, another exception occurred:

Traceback (most recent call last):
  File "/usr/local/lib/python3.10/site-packages/jupyter_cache/executors/utils.py", line 58, in single_nb_execution
    executenb(
  File "/usr/local/lib/python3.10/site-packages/nbclient/client.py", line 1319, in execute
    return NotebookClient(nb=nb, resources=resources, km=km, **kwargs).execute()
  File "/usr/local/lib/python3.10/site-packages/jupyter_core/utils/__init__.py", line 158, in wrapped
    return loop.run_until_complete(inner)
  File "/usr/local/lib/python3.10/asyncio/base_events.py", line 649, in run_until_complete
    return future.result()
  File "/usr/local/lib/python3.10/site-packages/nbclient/client.py", line 709, in async_execute
    await self.async_execute_cell(
  File "/usr/local/lib/python3.10/site-packages/nbclient/client.py", line 1062, in async_execute_cell
    await self._check_raise_for_error(cell, cell_index, exec_reply)
  File "/usr/local/lib/python3.10/site-packages/nbclient/client.py", line 918, in _check_raise_for_error
    raise CellExecutionError.from_cell_and_msg(cell, exec_reply_content)
nbclient.exceptions.CellExecutionError: An error occurred while executing the following cell:
------------------
# スクリープロットで因子数を探索
eigen = fa.get_eigenvalues()
left = list(range(1, len(eigen[0])+1))
fig, ax = plt.subplots()
ax.plot(left, eigen[0], marker="o")
ax.set(xlabel="因子数（固有値の数）", ylabel="固有値", title="スクリープロット")
ax.axhline(y=1, color="gray", linestyle="--", alpha=0.5)
fig.show()
------------------


[0;31m---------------------------------------------------------------------------[0m
[0;31mNameError[0m                                 Traceback (most recent call last)
Cell [0;32mIn[6], line 4[0m
[1;32m      2[0m eigen [38;5;241m=[39m fa[38;5;241m.[39mget_eigenvalues()
[1;32m      3[0m left [38;5;241m=[39m [38;5;28mlist[39m([38;5;28mrange[39m([38;5;241m1[39m, [38;5;28mlen[39m(eigen[[38;5;241m0[39m])[38;5;241m+[39m[38;5;241m1[39m))
[0;32m----> 4[0m fig, ax [38;5;241m=[39m [43mplt[49m[38;5;241m.[39msubplots()
[1;32m      5[0m ax[38;5;241m.[39mplot(left, eigen[[38;5;241m0[39m], marker[38;5;241m=[39m[38;5;124m"[39m[38;5;124mo[39m[38;5;124m"[39m)
[1;32m      6[0m ax[38;5;241m.[39mset(xlabel[38;5;241m=[39m[38;5;124m"[39m[38;5;124m因子数（固有値の数）[39m[38;5;124m"[39m, ylabel[38;5;241m=[39m[38;5;124m"[39m[38;5;124m固有値[39m[38;5;124m"[39m, title[38;5;241m=[39m[38;5;124m"[39m[38;5;124mスクリープロット[39m[38;5;124m"[39m)

[0;31mNameError[0m: name 'plt' is not defined

