Traceback (most recent call last):
  File "/usr/local/lib/python3.10/site-packages/jupyter_core/utils/__init__.py", line 154, in wrapped
    asyncio.get_running_loop()
RuntimeError: no running event loop

During handling of the above exception, another exception occurred:

Traceback (most recent call last):
  File "/usr/local/lib/python3.10/site-packages/jupyter_cache/executors/utils.py", line 58, in single_nb_execution
    executenb(
  File "/usr/local/lib/python3.10/site-packages/nbclient/client.py", line 1319, in execute
    return NotebookClient(nb=nb, resources=resources, km=km, **kwargs).execute()
  File "/usr/local/lib/python3.10/site-packages/jupyter_core/utils/__init__.py", line 158, in wrapped
    return loop.run_until_complete(inner)
  File "/usr/local/lib/python3.10/asyncio/base_events.py", line 649, in run_until_complete
    return future.result()
  File "/usr/local/lib/python3.10/site-packages/nbclient/client.py", line 709, in async_execute
    await self.async_execute_cell(
  File "/usr/local/lib/python3.10/site-packages/nbclient/client.py", line 1062, in async_execute_cell
    await self._check_raise_for_error(cell, cell_index, exec_reply)
  File "/usr/local/lib/python3.10/site-packages/nbclient/client.py", line 918, in _check_raise_for_error
    raise CellExecutionError.from_cell_and_msg(cell, exec_reply_content)
nbclient.exceptions.CellExecutionError: An error occurred while executing the following cell:
------------------
# データ生成（潜在相関0.6）
np.random.seed(1)
latent_x = np.random.normal(size=100)
latent_y = 0.6 * latent_x + np.random.normal(size=100)
X = (latent_x > 0.3).astype(int)
Y = (latent_y > 0.3).astype(int)

# 推定
rho_hat = tetrachoric_corr(X, Y)
print(f"推定されたテトラコリック相関: {rho_hat:.4f}")
------------------


[0;31m---------------------------------------------------------------------------[0m
[0;31mNameError[0m                                 Traceback (most recent call last)
Cell [0;32mIn[9], line 9[0m
[1;32m      6[0m Y [38;5;241m=[39m (latent_y [38;5;241m>[39m [38;5;241m0.3[39m)[38;5;241m.[39mastype([38;5;28mint[39m)
[1;32m      8[0m [38;5;66;03m# 推定[39;00m
[0;32m----> 9[0m rho_hat [38;5;241m=[39m [43mtetrachoric_corr[49m[43m([49m[43mX[49m[43m,[49m[43m [49m[43mY[49m[43m)[49m
[1;32m     10[0m [38;5;28mprint[39m([38;5;124mf[39m[38;5;124m"[39m[38;5;124m推定されたテトラコリック相関: [39m[38;5;132;01m{[39;00mrho_hat[38;5;132;01m:[39;00m[38;5;124m.4f[39m[38;5;132;01m}[39;00m[38;5;124m"[39m)

Cell [0;32mIn[8], line 13[0m, in [0;36mtetrachoric_corr[0;34m(x, y)[0m
[1;32m     10[0m px0 [38;5;241m=[39m (n00 [38;5;241m+[39m n01) [38;5;241m/[39m n
[1;32m     11[0m py0 [38;5;241m=[39m (n00 [38;5;241m+[39m n10) [38;5;241m/[39m n
[0;32m---> 13[0m tau_x [38;5;241m=[39m [43mnorm[49m[38;5;241m.[39mppf(px0)
[1;32m     14[0m tau_y [38;5;241m=[39m norm[38;5;241m.[39mppf(py0)
[1;32m     16[0m [38;5;28;01mdef[39;00m[38;5;250m [39m[38;5;21mneg_log_likelihood[39m(rho):

[0;31mNameError[0m: name 'norm' is not defined

