Traceback (most recent call last):
  File "/usr/local/lib/python3.10/site-packages/jupyter_cache/executors/utils.py", line 58, in single_nb_execution
    executenb(
  File "/usr/local/lib/python3.10/site-packages/nbclient/client.py", line 1319, in execute
    return NotebookClient(nb=nb, resources=resources, km=km, **kwargs).execute()
  File "/usr/local/lib/python3.10/site-packages/jupyter_core/utils/__init__.py", line 165, in wrapped
    return loop.run_until_complete(inner)
  File "/usr/local/lib/python3.10/asyncio/base_events.py", line 649, in run_until_complete
    return future.result()
  File "/usr/local/lib/python3.10/site-packages/nbclient/client.py", line 709, in async_execute
    await self.async_execute_cell(
  File "/usr/local/lib/python3.10/site-packages/nbclient/client.py", line 1062, in async_execute_cell
    await self._check_raise_for_error(cell, cell_index, exec_reply)
  File "/usr/local/lib/python3.10/site-packages/nbclient/client.py", line 918, in _check_raise_for_error
    raise CellExecutionError.from_cell_and_msg(cell, exec_reply_content)
nbclient.exceptions.CellExecutionError: An error occurred while executing the following cell:
------------------
# é–¾å€¤a, bã‚’æŽ¨å®š
from scipy.stats import norm
a = norm.ppf(P1, loc=0, scale=1)
b = norm.ppf(P2, loc=0, scale=1)

a = [-np.inf, *a]
b = [-np.inf, *b]

print(f"{a=}")
print(f"{b=}")
------------------


[0;31m---------------------------------------------------------------------------[0m
[0;31mNameError[0m                                 Traceback (most recent call last)
Cell [0;32mIn[11], line 3[0m
[1;32m      1[0m [38;5;66;03m# é–¾å€¤a, bã‚’æŽ¨å®š[39;00m
[1;32m      2[0m [38;5;28;01mfrom[39;00m[38;5;250m [39m[38;5;21;01mscipy[39;00m[38;5;21;01m.[39;00m[38;5;21;01mstats[39;00m[38;5;250m [39m[38;5;28;01mimport[39;00m norm
[0;32m----> 3[0m a [38;5;241m=[39m norm[38;5;241m.[39mppf([43mP1[49m, loc[38;5;241m=[39m[38;5;241m0[39m, scale[38;5;241m=[39m[38;5;241m1[39m)
[1;32m      4[0m b [38;5;241m=[39m norm[38;5;241m.[39mppf(P2, loc[38;5;241m=[39m[38;5;241m0[39m, scale[38;5;241m=[39m[38;5;241m1[39m)
[1;32m      6[0m a [38;5;241m=[39m [[38;5;241m-[39mnp[38;5;241m.[39minf, [38;5;241m*[39ma]

[0;31mNameError[0m: name 'P1' is not defined

