Traceback (most recent call last):
  File "/usr/local/lib/python3.9/site-packages/jupyter_cache/executors/utils.py", line 58, in single_nb_execution
    executenb(
  File "/usr/local/lib/python3.9/site-packages/nbclient/client.py", line 1314, in execute
    return NotebookClient(nb=nb, resources=resources, km=km, **kwargs).execute()
  File "/usr/local/lib/python3.9/site-packages/jupyter_core/utils/__init__.py", line 165, in wrapped
    return loop.run_until_complete(inner)
  File "/usr/local/lib/python3.9/asyncio/base_events.py", line 647, in run_until_complete
    return future.result()
  File "/usr/local/lib/python3.9/site-packages/nbclient/client.py", line 709, in async_execute
    await self.async_execute_cell(
  File "/usr/local/lib/python3.9/site-packages/nbclient/client.py", line 1062, in async_execute_cell
    await self._check_raise_for_error(cell, cell_index, exec_reply)
  File "/usr/local/lib/python3.9/site-packages/nbclient/client.py", line 918, in _check_raise_for_error
    raise CellExecutionError.from_cell_and_msg(cell, exec_reply_content)
nbclient.exceptions.CellExecutionError: An error occurred while executing the following cell:
------------------
import numpy as np
import matplotlib.pyplot as plt
from scipy.stats import norm

w = 0.3
n = 1000
x1 = norm.rvs(loc=0, scale=1, size=n, random_state=0)
x2 = w * x1 + (1 - w) * norm.rvs(loc=0, scale=1, size=n, random_state=1)
X = np.append(x1.reshape(-1, 1), x2.reshape(-1, 1), axis=1)
df = pd.DataFrame(X)

fig, ax = plt.subplots(figsize=[5, 4])
ax.scatter(x1, x2)
ax.set(xlabel="x1", ylabel="x2", xlim=(-3, 3), ylim=(-3, 3))
fig.show()
------------------


[0;31m---------------------------------------------------------------------------[0m
[0;31mNameError[0m                                 Traceback (most recent call last)
Cell [0;32mIn[1], line 10[0m
[1;32m      8[0m x2 [38;5;241m=[39m w [38;5;241m*[39m x1 [38;5;241m+[39m ([38;5;241m1[39m [38;5;241m-[39m w) [38;5;241m*[39m norm[38;5;241m.[39mrvs(loc[38;5;241m=[39m[38;5;241m0[39m, scale[38;5;241m=[39m[38;5;241m1[39m, size[38;5;241m=[39mn, random_state[38;5;241m=[39m[38;5;241m1[39m)
[1;32m      9[0m X [38;5;241m=[39m np[38;5;241m.[39mappend(x1[38;5;241m.[39mreshape([38;5;241m-[39m[38;5;241m1[39m, [38;5;241m1[39m), x2[38;5;241m.[39mreshape([38;5;241m-[39m[38;5;241m1[39m, [38;5;241m1[39m), axis[38;5;241m=[39m[38;5;241m1[39m)
[0;32m---> 10[0m df [38;5;241m=[39m [43mpd[49m[38;5;241m.[39mDataFrame(X)
[1;32m     12[0m fig, ax [38;5;241m=[39m plt[38;5;241m.[39msubplots(figsize[38;5;241m=[39m[[38;5;241m5[39m, [38;5;241m4[39m])
[1;32m     13[0m ax[38;5;241m.[39mscatter(x1, x2)

[0;31mNameError[0m: name 'pd' is not defined

