Traceback (most recent call last):
  File "/usr/local/lib/python3.10/site-packages/jupyter_cache/executors/utils.py", line 58, in single_nb_execution
    executenb(
  File "/usr/local/lib/python3.10/site-packages/nbclient/client.py", line 1305, in execute
    return NotebookClient(nb=nb, resources=resources, km=km, **kwargs).execute()
  File "/usr/local/lib/python3.10/site-packages/jupyter_core/utils/__init__.py", line 165, in wrapped
    return loop.run_until_complete(inner)
  File "/usr/local/lib/python3.10/asyncio/base_events.py", line 649, in run_until_complete
    return future.result()
  File "/usr/local/lib/python3.10/site-packages/nbclient/client.py", line 705, in async_execute
    await self.async_execute_cell(
  File "/usr/local/lib/python3.10/site-packages/nbclient/client.py", line 1058, in async_execute_cell
    await self._check_raise_for_error(cell, cell_index, exec_reply)
  File "/usr/local/lib/python3.10/site-packages/nbclient/client.py", line 914, in _check_raise_for_error
    raise CellExecutionError.from_cell_and_msg(cell, exec_reply_content)
nbclient.exceptions.CellExecutionError: An error occurred while executing the following cell:
------------------
D = X.shape[1]
K = 3

# 乱数でμ初期化
np.random.seed(0)
mu = np.random.rand(D, K)
mu
------------------


[0;31m---------------------------------------------------------------------------[0m
[0;31mNameError[0m                                 Traceback (most recent call last)
Cell [0;32mIn[3], line 5[0m
[1;32m      2[0m K [38;5;241m=[39m [38;5;241m3[39m
[1;32m      4[0m [38;5;66;03m# 乱数でμ初期化[39;00m
[0;32m----> 5[0m [43mnp[49m[38;5;241m.[39mrandom[38;5;241m.[39mseed([38;5;241m0[39m)
[1;32m      6[0m mu [38;5;241m=[39m np[38;5;241m.[39mrandom[38;5;241m.[39mrand(D, K)
[1;32m      7[0m mu

[0;31mNameError[0m: name 'np' is not defined

