Traceback (most recent call last):
  File "/__w/notes/notes/.venv/lib/python3.10/site-packages/jupyter_core/utils/__init__.py", line 154, in wrapped
    asyncio.get_running_loop()
RuntimeError: no running event loop

During handling of the above exception, another exception occurred:

Traceback (most recent call last):
  File "/__w/notes/notes/.venv/lib/python3.10/site-packages/jupyter_cache/executors/utils.py", line 58, in single_nb_execution
    executenb(
  File "/__w/notes/notes/.venv/lib/python3.10/site-packages/nbclient/client.py", line 1319, in execute
    return NotebookClient(nb=nb, resources=resources, km=km, **kwargs).execute()
  File "/__w/notes/notes/.venv/lib/python3.10/site-packages/jupyter_core/utils/__init__.py", line 158, in wrapped
    return loop.run_until_complete(inner)
  File "/usr/local/lib/python3.10/asyncio/base_events.py", line 649, in run_until_complete
    return future.result()
  File "/__w/notes/notes/.venv/lib/python3.10/site-packages/nbclient/client.py", line 709, in async_execute
    await self.async_execute_cell(
  File "/__w/notes/notes/.venv/lib/python3.10/site-packages/nbclient/client.py", line 1062, in async_execute_cell
    await self._check_raise_for_error(cell, cell_index, exec_reply)
  File "/__w/notes/notes/.venv/lib/python3.10/site-packages/nbclient/client.py", line 918, in _check_raise_for_error
    raise CellExecutionError.from_cell_and_msg(cell, exec_reply_content)
nbclient.exceptions.CellExecutionError: An error occurred while executing the following cell:
------------------
# indexと値の取得
user_idx, users = pd.factorize(df_long["user"])
item_idx, items = pd.factorize(df_long["item"])
responses = df_long["response"].to_numpy()

import pymc as pm
model = pm.Model(coords={"user": df.index, "item": df.columns})
with model:
    # 観測値の配列
    response_obs = pm.ConstantData("responses", responses)

    # 2PLM
    theta = pm.Normal("theta", mu=0.0, sigma=1.0, dims="user")
    a = pm.HalfNormal("a", sigma=1.0, dims="item")
    beta = pm.Normal("beta", mu=0.0, sigma=1.0, dims="item")
    logit_p = pm.Deterministic("logit_p", a[item_idx] * (theta[user_idx] - beta[item_idx]))

    # ベルヌーイ分布（pではなくlogit_pの引数に渡すことでシグモイド関数の計算をpymc側にまかせている）
    obs = pm.Bernoulli("obs", logit_p=logit_p, observed=response_obs)

g = pm.model_to_graphviz(model)
g
------------------


[0;31m---------------------------------------------------------------------------[0m
[0;31mAttributeError[0m                            Traceback (most recent call last)
Cell [0;32mIn[6], line 10[0m
[1;32m      7[0m model [38;5;241m=[39m pm[38;5;241m.[39mModel(coords[38;5;241m=[39m{[38;5;124m"[39m[38;5;124muser[39m[38;5;124m"[39m: df[38;5;241m.[39mindex, [38;5;124m"[39m[38;5;124mitem[39m[38;5;124m"[39m: df[38;5;241m.[39mcolumns})
[1;32m      8[0m [38;5;28;01mwith[39;00m model:
[1;32m      9[0m     [38;5;66;03m# 観測値の配列[39;00m
[0;32m---> 10[0m     response_obs [38;5;241m=[39m [43mpm[49m[38;5;241;43m.[39;49m[43mConstantData[49m([38;5;124m"[39m[38;5;124mresponses[39m[38;5;124m"[39m, responses)
[1;32m     12[0m     [38;5;66;03m# 2PLM[39;00m
[1;32m     13[0m     theta [38;5;241m=[39m pm[38;5;241m.[39mNormal([38;5;124m"[39m[38;5;124mtheta[39m[38;5;124m"[39m, mu[38;5;241m=[39m[38;5;241m0.0[39m, sigma[38;5;241m=[39m[38;5;241m1.0[39m, dims[38;5;241m=[39m[38;5;124m"[39m[38;5;124muser[39m[38;5;124m"[39m)

[0;31mAttributeError[0m: module 'pymc' has no attribute 'ConstantData'

