Traceback (most recent call last):
  File "/__w/notes/notes/.venv/lib/python3.10/site-packages/jupyter_core/utils/__init__.py", line 154, in wrapped
    asyncio.get_running_loop()
RuntimeError: no running event loop

During handling of the above exception, another exception occurred:

Traceback (most recent call last):
  File "/__w/notes/notes/.venv/lib/python3.10/site-packages/jupyter_cache/executors/utils.py", line 58, in single_nb_execution
    executenb(
  File "/__w/notes/notes/.venv/lib/python3.10/site-packages/nbclient/client.py", line 1319, in execute
    return NotebookClient(nb=nb, resources=resources, km=km, **kwargs).execute()
  File "/__w/notes/notes/.venv/lib/python3.10/site-packages/jupyter_core/utils/__init__.py", line 158, in wrapped
    return loop.run_until_complete(inner)
  File "/usr/local/lib/python3.10/asyncio/base_events.py", line 649, in run_until_complete
    return future.result()
  File "/__w/notes/notes/.venv/lib/python3.10/site-packages/nbclient/client.py", line 709, in async_execute
    await self.async_execute_cell(
  File "/__w/notes/notes/.venv/lib/python3.10/site-packages/nbclient/client.py", line 1062, in async_execute_cell
    await self._check_raise_for_error(cell, cell_index, exec_reply)
  File "/__w/notes/notes/.venv/lib/python3.10/site-packages/nbclient/client.py", line 918, in _check_raise_for_error
    raise CellExecutionError.from_cell_and_msg(cell, exec_reply_content)
nbclient.exceptions.CellExecutionError: An error occurred while executing the following cell:
------------------
Q_model = GradientBoostingRegressor(random_state=0, n_estimators=200, max_depth=3)

X_w_treatment = confounders.copy()
X_w_treatment["treatment"] = treatment

X_train, X_test, y_train, y_test = train_test_split(X_w_treatment, outcome, test_size=0.2)
Q_model.fit(X_train, y_train)
y_pred = Q_model.predict(X_test)
------------------


[0;31m---------------------------------------------------------------------------[0m
[0;31mNameError[0m                                 Traceback (most recent call last)
Cell [0;32mIn[3], line 3[0m
[1;32m      1[0m Q_model [38;5;241m=[39m GradientBoostingRegressor(random_state[38;5;241m=[39m[38;5;241m0[39m, n_estimators[38;5;241m=[39m[38;5;241m200[39m, max_depth[38;5;241m=[39m[38;5;241m3[39m)
[0;32m----> 3[0m X_w_treatment [38;5;241m=[39m [43mconfounders[49m[38;5;241m.[39mcopy()
[1;32m      4[0m X_w_treatment[[38;5;124m"[39m[38;5;124mtreatment[39m[38;5;124m"[39m] [38;5;241m=[39m treatment
[1;32m      6[0m X_train, X_test, y_train, y_test [38;5;241m=[39m train_test_split(X_w_treatment, outcome, test_size[38;5;241m=[39m[38;5;241m0.2[39m)

[0;31mNameError[0m: name 'confounders' is not defined

