Traceback (most recent call last):
  File "/__w/notes/notes/.venv/lib/python3.10/site-packages/jupyter_core/utils/__init__.py", line 154, in wrapped
    asyncio.get_running_loop()
RuntimeError: no running event loop

During handling of the above exception, another exception occurred:

Traceback (most recent call last):
  File "/__w/notes/notes/.venv/lib/python3.10/site-packages/jupyter_cache/executors/utils.py", line 58, in single_nb_execution
    executenb(
  File "/__w/notes/notes/.venv/lib/python3.10/site-packages/nbclient/client.py", line 1319, in execute
    return NotebookClient(nb=nb, resources=resources, km=km, **kwargs).execute()
  File "/__w/notes/notes/.venv/lib/python3.10/site-packages/jupyter_core/utils/__init__.py", line 158, in wrapped
    return loop.run_until_complete(inner)
  File "/usr/local/lib/python3.10/asyncio/base_events.py", line 649, in run_until_complete
    return future.result()
  File "/__w/notes/notes/.venv/lib/python3.10/site-packages/nbclient/client.py", line 709, in async_execute
    await self.async_execute_cell(
  File "/__w/notes/notes/.venv/lib/python3.10/site-packages/nbclient/client.py", line 1062, in async_execute_cell
    await self._check_raise_for_error(cell, cell_index, exec_reply)
  File "/__w/notes/notes/.venv/lib/python3.10/site-packages/nbclient/client.py", line 918, in _check_raise_for_error
    raise CellExecutionError.from_cell_and_msg(cell, exec_reply_content)
nbclient.exceptions.CellExecutionError: An error occurred while executing the following cell:
------------------
# contour plot for the estimate
# x軸が処置変数の部分決定係数
# y軸が結果変数の部分決定係数
darfur_sense.plot()
------------------


[0;31m---------------------------------------------------------------------------[0m
[0;31mAttributeError[0m                            Traceback (most recent call last)
Cell [0;32mIn[6], line 4[0m
[1;32m      1[0m [38;5;66;03m# contour plot for the estimate[39;00m
[1;32m      2[0m [38;5;66;03m# x軸が処置変数の部分決定係数[39;00m
[1;32m      3[0m [38;5;66;03m# y軸が結果変数の部分決定係数[39;00m
[0;32m----> 4[0m [43mdarfur_sense[49m[38;5;241;43m.[39;49m[43mplot[49m[43m([49m[43m)[49m

File [0;32m/__w/notes/notes/.venv/lib/python3.10/site-packages/sensemakr/main.py:443[0m, in [0;36mSensemakr.plot[0;34m(self, plot_type, sensitivity_of, **kwargs)[0m
[1;32m    408[0m [38;5;250m[39m[38;5;124;03m"""[39;00m
[1;32m    409[0m [38;5;124;03mProvide the contour and extreme scenario sensitivity plots of the sensitivity analysis results obtained with the function Sensemakr.[39;00m
[1;32m    410[0m 
[0;32m   (...)[0m
[1;32m    440[0m [38;5;124;03m>>> sensitivity = smkr.Sensemakr(fitted_model, treatment = "directlyharmed", benchmark_covariates = "female", kd = [1, 2, 3])[39;00m
[1;32m    441[0m [38;5;124;03m"""[39;00m
[1;32m    442[0m [38;5;28;01mif[39;00m plot_type [38;5;241m==[39m [38;5;124m'[39m[38;5;124mcontour[39m[38;5;124m'[39m:
[0;32m--> 443[0m     [43msensitivity_plots[49m[38;5;241;43m.[39;49m[43movb_contour_plot[49m[43m([49m[43msense_obj[49m[38;5;241;43m=[39;49m[38;5;28;43mself[39;49m[43m,[49m[43msensitivity_of[49m[38;5;241;43m=[39;49m[43msensitivity_of[49m[43m,[49m[38;5;241;43m*[39;49m[38;5;241;43m*[39;49m[43mkwargs[49m[43m)[49m
[1;32m    444[0m [38;5;28;01melif[39;00m (plot_type [38;5;241m==[39m [38;5;124m'[39m[38;5;124mextreme[39m[38;5;124m'[39m) [38;5;129;01mand[39;00m (sensitivity_of [38;5;241m==[39m [38;5;124m'[39m[38;5;124mt-value[39m[38;5;124m'[39m):
[1;32m    445[0m     sys[38;5;241m.[39mexit([38;5;124m'[39m[38;5;124mError: extreme plot for t-value has not been implemented yet[39m[38;5;124m'[39m)

File [0;32m/__w/notes/notes/.venv/lib/python3.10/site-packages/sensemakr/sensitivity_plots.py:186[0m, in [0;36movb_contour_plot[0;34m(sense_obj, sensitivity_of, model, treatment, estimate, se, dof, benchmark_covariates, kd, ky, r2dz_x, r2yz_dx, bound_label, reduce, estimate_threshold, t_threshold, lim, lim_y, col_contour, col_thr_line, label_text, label_bump_x, label_bump_y, xlab, ylab, plot_margin_fraction, round_dig, n_levels)[0m
[1;32m    184[0m [38;5;28;01mif[39;00m round_thr [38;5;129;01min[39;00m cs_levels:
[1;32m    185[0m     threshold_index [38;5;241m=[39m cs_levels[38;5;241m.[39mindex(round_thr)
[0;32m--> 186[0m     [43mCS[49m[38;5;241;43m.[39;49m[43mcollections[49m[threshold_index][38;5;241m.[39mremove()
[1;32m    187[0m     [38;5;66;03m# There's a conflict in matplotlib 3.8.2 with this remove method and ax.clabel[39;00m
[1;32m    188[0m     [38;5;66;03m# I'm currently commenting the line ax.clabel out but maybe there's a different way to do remove[39;00m
[1;32m    189[0m     [38;5;66;03m#ax.clabel(CS, inline=1, fontsize=8, fmt="%1.3g", colors="gray", levels=np.delete(CS.levels, threshold_index))[39;00m
[1;32m    190[0m [38;5;28;01melse[39;00m:
[1;32m    191[0m     ax[38;5;241m.[39mclabel(CS, inline[38;5;241m=[39m[38;5;241m1[39m, fontsize[38;5;241m=[39m[38;5;241m8[39m, fmt[38;5;241m=[39m[38;5;124m"[39m[38;5;132;01m%1.3g[39;00m[38;5;124m"[39m, colors[38;5;241m=[39m[38;5;124m"[39m[38;5;124mgray[39m[38;5;124m"[39m, levels[38;5;241m=[39mCS[38;5;241m.[39mlevels)

[0;31mAttributeError[0m: 'QuadContourSet' object has no attribute 'collections'

