Traceback (most recent call last):
  File "/usr/local/lib/python3.10/site-packages/jupyter_core/utils/__init__.py", line 154, in wrapped
    asyncio.get_running_loop()
RuntimeError: no running event loop

During handling of the above exception, another exception occurred:

Traceback (most recent call last):
  File "/usr/local/lib/python3.10/site-packages/jupyter_cache/executors/utils.py", line 58, in single_nb_execution
    executenb(
  File "/usr/local/lib/python3.10/site-packages/nbclient/client.py", line 1319, in execute
    return NotebookClient(nb=nb, resources=resources, km=km, **kwargs).execute()
  File "/usr/local/lib/python3.10/site-packages/jupyter_core/utils/__init__.py", line 158, in wrapped
    return loop.run_until_complete(inner)
  File "/usr/local/lib/python3.10/asyncio/base_events.py", line 649, in run_until_complete
    return future.result()
  File "/usr/local/lib/python3.10/site-packages/nbclient/client.py", line 709, in async_execute
    await self.async_execute_cell(
  File "/usr/local/lib/python3.10/site-packages/nbclient/client.py", line 1062, in async_execute_cell
    await self._check_raise_for_error(cell, cell_index, exec_reply)
  File "/usr/local/lib/python3.10/site-packages/nbclient/client.py", line 918, in _check_raise_for_error
    raise CellExecutionError.from_cell_and_msg(cell, exec_reply_content)
nbclient.exceptions.CellExecutionError: An error occurred while executing the following cell:
------------------
# äºˆæ¸¬å€¤ã‚’ç®—å‡º
y_pred = model.predict(X)

# äºˆæ¸¬èª¤å·®ã‚’è©•ä¾¡
from sklearn.metrics import mean_squared_error
rmse = mean_squared_error(y, y_pred, squared=False)

print(f"RMSE: {rmse:.3f}")
------------------


[0;31m---------------------------------------------------------------------------[0m
[0;31mTypeError[0m                                 Traceback (most recent call last)
Cell [0;32mIn[8], line 6[0m
[1;32m      4[0m [38;5;66;03m# äºˆæ¸¬èª¤å·®ã‚’è©•ä¾¡[39;00m
[1;32m      5[0m [38;5;28;01mfrom[39;00m[38;5;250m [39m[38;5;21;01msklearn[39;00m[38;5;21;01m.[39;00m[38;5;21;01mmetrics[39;00m[38;5;250m [39m[38;5;28;01mimport[39;00m mean_squared_error
[0;32m----> 6[0m rmse [38;5;241m=[39m [43mmean_squared_error[49m[43m([49m[43my[49m[43m,[49m[43m [49m[43my_pred[49m[43m,[49m[43m [49m[43msquared[49m[38;5;241;43m=[39;49m[38;5;28;43;01mFalse[39;49;00m[43m)[49m
[1;32m      8[0m [38;5;28mprint[39m([38;5;124mf[39m[38;5;124m"[39m[38;5;124mRMSE: [39m[38;5;132;01m{[39;00mrmse[38;5;132;01m:[39;00m[38;5;124m.3f[39m[38;5;132;01m}[39;00m[38;5;124m"[39m)

File [0;32m/usr/local/lib/python3.10/site-packages/sklearn/utils/_param_validation.py:196[0m, in [0;36mvalidate_params.<locals>.decorator.<locals>.wrapper[0;34m(*args, **kwargs)[0m
[1;32m    193[0m func_sig [38;5;241m=[39m signature(func)
[1;32m    195[0m [38;5;66;03m# Map *args/**kwargs to the function signature[39;00m
[0;32m--> 196[0m params [38;5;241m=[39m [43mfunc_sig[49m[38;5;241;43m.[39;49m[43mbind[49m[43m([49m[38;5;241;43m*[39;49m[43margs[49m[43m,[49m[43m [49m[38;5;241;43m*[39;49m[38;5;241;43m*[39;49m[43mkwargs[49m[43m)[49m
[1;32m    197[0m params[38;5;241m.[39mapply_defaults()
[1;32m    199[0m [38;5;66;03m# ignore self/cls and positional/keyword markers[39;00m

File [0;32m/usr/local/lib/python3.10/inspect.py:3186[0m, in [0;36mSignature.bind[0;34m(self, *args, **kwargs)[0m
[1;32m   3181[0m [38;5;28;01mdef[39;00m[38;5;250m [39m[38;5;21mbind[39m([38;5;28mself[39m, [38;5;241m/[39m, [38;5;241m*[39margs, [38;5;241m*[39m[38;5;241m*[39mkwargs):
[1;32m   3182[0m [38;5;250m    [39m[38;5;124;03m"""Get a BoundArguments object, that maps the passed `args`[39;00m
[1;32m   3183[0m [38;5;124;03m    and `kwargs` to the function's signature.  Raises `TypeError`[39;00m
[1;32m   3184[0m [38;5;124;03m    if the passed arguments can not be bound.[39;00m
[1;32m   3185[0m [38;5;124;03m    """[39;00m
[0;32m-> 3186[0m     [38;5;28;01mreturn[39;00m [38;5;28;43mself[39;49m[38;5;241;43m.[39;49m[43m_bind[49m[43m([49m[43margs[49m[43m,[49m[43m [49m[43mkwargs[49m[43m)[49m

File [0;32m/usr/local/lib/python3.10/inspect.py:3175[0m, in [0;36mSignature._bind[0;34m(self, args, kwargs, partial)[0m
[1;32m   3173[0m         arguments[kwargs_param[38;5;241m.[39mname] [38;5;241m=[39m kwargs
[1;32m   3174[0m     [38;5;28;01melse[39;00m:
[0;32m-> 3175[0m         [38;5;28;01mraise[39;00m [38;5;167;01mTypeError[39;00m(
[1;32m   3176[0m             [38;5;124m'[39m[38;5;124mgot an unexpected keyword argument [39m[38;5;132;01m{arg!r}[39;00m[38;5;124m'[39m[38;5;241m.[39mformat(
[1;32m   3177[0m                 arg[38;5;241m=[39m[38;5;28mnext[39m([38;5;28miter[39m(kwargs))))
[1;32m   3179[0m [38;5;28;01mreturn[39;00m [38;5;28mself[39m[38;5;241m.[39m_bound_arguments_cls([38;5;28mself[39m, arguments)

[0;31mTypeError[0m: got an unexpected keyword argument 'squared'

