Traceback (most recent call last):
  File "/__w/notes/notes/.venv/lib/python3.10/site-packages/jupyter_core/utils/__init__.py", line 154, in wrapped
    asyncio.get_running_loop()
RuntimeError: no running event loop

During handling of the above exception, another exception occurred:

Traceback (most recent call last):
  File "/__w/notes/notes/.venv/lib/python3.10/site-packages/jupyter_cache/executors/utils.py", line 58, in single_nb_execution
    executenb(
  File "/__w/notes/notes/.venv/lib/python3.10/site-packages/nbclient/client.py", line 1319, in execute
    return NotebookClient(nb=nb, resources=resources, km=km, **kwargs).execute()
  File "/__w/notes/notes/.venv/lib/python3.10/site-packages/jupyter_core/utils/__init__.py", line 158, in wrapped
    return loop.run_until_complete(inner)
  File "/usr/local/lib/python3.10/asyncio/base_events.py", line 649, in run_until_complete
    return future.result()
  File "/__w/notes/notes/.venv/lib/python3.10/site-packages/nbclient/client.py", line 709, in async_execute
    await self.async_execute_cell(
  File "/__w/notes/notes/.venv/lib/python3.10/site-packages/nbclient/client.py", line 1062, in async_execute_cell
    await self._check_raise_for_error(cell, cell_index, exec_reply)
  File "/__w/notes/notes/.venv/lib/python3.10/site-packages/nbclient/client.py", line 918, in _check_raise_for_error
    raise CellExecutionError.from_cell_and_msg(cell, exec_reply_content)
nbclient.exceptions.CellExecutionError: An error occurred while executing the following cell:
------------------
reader = Reader(rating_scale=(1, 5))
data = Dataset.load_from_df(df_custom[["userid", "itemid", "rating"]], reader)
------------------


[0;31m---------------------------------------------------------------------------[0m
[0;31mNameError[0m                                 Traceback (most recent call last)
Cell [0;32mIn[4], line 2[0m
[1;32m      1[0m reader [38;5;241m=[39m Reader(rating_scale[38;5;241m=[39m([38;5;241m1[39m, [38;5;241m5[39m))
[0;32m----> 2[0m data [38;5;241m=[39m Dataset[38;5;241m.[39mload_from_df([43mdf_custom[49m[[[38;5;124m"[39m[38;5;124muserid[39m[38;5;124m"[39m, [38;5;124m"[39m[38;5;124mitemid[39m[38;5;124m"[39m, [38;5;124m"[39m[38;5;124mrating[39m[38;5;124m"[39m]], reader)

[0;31mNameError[0m: name 'df_custom' is not defined

