Traceback (most recent call last):
  File "/usr/local/lib/python3.10/site-packages/jupyter_core/utils/__init__.py", line 154, in wrapped
    asyncio.get_running_loop()
RuntimeError: no running event loop

During handling of the above exception, another exception occurred:

Traceback (most recent call last):
  File "/usr/local/lib/python3.10/site-packages/jupyter_cache/executors/utils.py", line 58, in single_nb_execution
    executenb(
  File "/usr/local/lib/python3.10/site-packages/nbclient/client.py", line 1319, in execute
    return NotebookClient(nb=nb, resources=resources, km=km, **kwargs).execute()
  File "/usr/local/lib/python3.10/site-packages/jupyter_core/utils/__init__.py", line 158, in wrapped
    return loop.run_until_complete(inner)
  File "/usr/local/lib/python3.10/asyncio/base_events.py", line 649, in run_until_complete
    return future.result()
  File "/usr/local/lib/python3.10/site-packages/nbclient/client.py", line 709, in async_execute
    await self.async_execute_cell(
  File "/usr/local/lib/python3.10/site-packages/nbclient/client.py", line 1062, in async_execute_cell
    await self._check_raise_for_error(cell, cell_index, exec_reply)
  File "/usr/local/lib/python3.10/site-packages/nbclient/client.py", line 918, in _check_raise_for_error
    raise CellExecutionError.from_cell_and_msg(cell, exec_reply_content)
nbclient.exceptions.CellExecutionError: An error occurred while executing the following cell:
------------------
rho = 0.05
cov = np.array([[1, rho], [rho, 1]])
X = multivariate_normal.rvs(cov=cov, size=100, random_state=0)
x = X[:, 0]
y = 1 * (X[:, 1] > 0.5)
biserial_correlation(x,  y)
------------------


[0;31m---------------------------------------------------------------------------[0m
[0;31mNameError[0m                                 Traceback (most recent call last)
Cell [0;32mIn[5], line 3[0m
[1;32m      1[0m rho [38;5;241m=[39m [38;5;241m0.05[39m
[1;32m      2[0m cov [38;5;241m=[39m np[38;5;241m.[39marray([[[38;5;241m1[39m, rho], [rho, [38;5;241m1[39m]])
[0;32m----> 3[0m X [38;5;241m=[39m [43mmultivariate_normal[49m[38;5;241m.[39mrvs(cov[38;5;241m=[39mcov, size[38;5;241m=[39m[38;5;241m100[39m, random_state[38;5;241m=[39m[38;5;241m0[39m)
[1;32m      4[0m x [38;5;241m=[39m X[:, [38;5;241m0[39m]
[1;32m      5[0m y [38;5;241m=[39m [38;5;241m1[39m [38;5;241m*[39m (X[:, [38;5;241m1[39m] [38;5;241m>[39m [38;5;241m0.5[39m)

[0;31mNameError[0m: name 'multivariate_normal' is not defined

