Traceback (most recent call last):
  File "/usr/local/lib/python3.10/site-packages/jupyter_core/utils/__init__.py", line 154, in wrapped
    asyncio.get_running_loop()
RuntimeError: no running event loop

During handling of the above exception, another exception occurred:

Traceback (most recent call last):
  File "/usr/local/lib/python3.10/site-packages/jupyter_cache/executors/utils.py", line 58, in single_nb_execution
    executenb(
  File "/usr/local/lib/python3.10/site-packages/nbclient/client.py", line 1319, in execute
    return NotebookClient(nb=nb, resources=resources, km=km, **kwargs).execute()
  File "/usr/local/lib/python3.10/site-packages/jupyter_core/utils/__init__.py", line 158, in wrapped
    return loop.run_until_complete(inner)
  File "/usr/local/lib/python3.10/asyncio/base_events.py", line 649, in run_until_complete
    return future.result()
  File "/usr/local/lib/python3.10/site-packages/nbclient/client.py", line 709, in async_execute
    await self.async_execute_cell(
  File "/usr/local/lib/python3.10/site-packages/nbclient/client.py", line 1062, in async_execute_cell
    await self._check_raise_for_error(cell, cell_index, exec_reply)
  File "/usr/local/lib/python3.10/site-packages/nbclient/client.py", line 918, in _check_raise_for_error
    raise CellExecutionError.from_cell_and_msg(cell, exec_reply_content)
nbclient.exceptions.CellExecutionError: An error occurred while executing the following cell:
------------------
rho = 0.75
Cov = np.array([[1, rho], [rho, 1]])
X = multivariate_normal.rvs(mean=mean, cov=Cov, size=n, random_state=0)
df = pd.DataFrame(X, columns=["x", "y"])
df["y"], _ = pd.cut(df["y"], bins=3).factorize(sort=True)
polyserial_correlation(df["x"], df["y"])
------------------


[0;31m---------------------------------------------------------------------------[0m
[0;31mNameError[0m                                 Traceback (most recent call last)
Cell [0;32mIn[2], line 3[0m
[1;32m      1[0m rho [38;5;241m=[39m [38;5;241m0.75[39m
[1;32m      2[0m Cov [38;5;241m=[39m np[38;5;241m.[39marray([[[38;5;241m1[39m, rho], [rho, [38;5;241m1[39m]])
[0;32m----> 3[0m X [38;5;241m=[39m [43mmultivariate_normal[49m[38;5;241m.[39mrvs(mean[38;5;241m=[39mmean, cov[38;5;241m=[39mCov, size[38;5;241m=[39mn, random_state[38;5;241m=[39m[38;5;241m0[39m)
[1;32m      4[0m df [38;5;241m=[39m pd[38;5;241m.[39mDataFrame(X, columns[38;5;241m=[39m[[38;5;124m"[39m[38;5;124mx[39m[38;5;124m"[39m, [38;5;124m"[39m[38;5;124my[39m[38;5;124m"[39m])
[1;32m      5[0m df[[38;5;124m"[39m[38;5;124my[39m[38;5;124m"[39m], _ [38;5;241m=[39m pd[38;5;241m.[39mcut(df[[38;5;124m"[39m[38;5;124my[39m[38;5;124m"[39m], bins[38;5;241m=[39m[38;5;241m3[39m)[38;5;241m.[39mfactorize(sort[38;5;241m=[39m[38;5;28;01mTrue[39;00m)

[0;31mNameError[0m: name 'multivariate_normal' is not defined

